<?xml version="1.0" encoding="utf-8"?>
<!-- This URDF was automatically created by SolidWorks to URDF Exporter! Originally created by Stephen Brawner (brawner@gmail.com) 
     Commit Version: 1.6.0-4-g7f85cfe  Build Version: 1.6.7995.38578
     For more information, please see http://wiki.ros.org/sw_urdf_exporter -->
<robot
  name="manipulator_assembly_to_URDF">
  <link
    name="base_link">
    <inertial>
      <origin
        xyz="0.078917 0.036505 0.00014694"
        rpy="0 0 0" />
      <mass
        value="0.80306" />
      <inertia
        ixx="0.00058252"
        ixy="5.9124E-06"
        ixz="2.2276E-06"
        iyy="0.0012075"
        iyz="3.7681E-07"
        izz="0.0015885" />
    </inertial>
    <visual>
      <origin
        xyz="0 0 0"
        rpy="0 0 0" />
      <geometry>
        <mesh
          filename="package://manipulator_assembly_to_URDF/meshes/base_link.STL" />
      </geometry>
      <material
        name="">
        <color
          rgba="1 0.54902 0 1" />
      </material>
    </visual>
    <collision>
      <origin
        xyz="0 0 0"
        rpy="0 0 0" />
      <geometry>
        <mesh
          filename="package://manipulator_assembly_to_URDF/meshes/base_link.STL" />
      </geometry>
    </collision>
  </link>
  <link
    name="link_1">
    <inertial>
      <origin
        xyz="0.0058496 4.5029E-05 0.029826"
        rpy="0 0 0" />
      <mass
        value="1.2963" />
      <inertia
        ixx="0.00036464"
        ixy="6.1082E-07"
        ixz="5.4471E-06"
        iyy="0.00057711"
        iyz="4.4643E-07"
        izz="0.0006064" />
    </inertial>
    <visual>
      <origin
        xyz="0 0 0"
        rpy="0 0 0" />
      <geometry>
        <mesh
          filename="package://manipulator_assembly_to_URDF/meshes/link_1.STL" />
      </geometry>
      <material
        name="">
        <color
          rgba="0.64706 0.61961 0.58824 1" />
      </material>
    </visual>
    <collision>
      <origin
        xyz="0 0 0"
        rpy="0 0 0" />
      <geometry>
        <mesh
          filename="package://manipulator_assembly_to_URDF/meshes/link_1.STL" />
      </geometry>
    </collision>
  </link>
  <joint
    name="joint_1"
    type="continuous">
    <origin
      xyz="0 0 0"
      rpy="0 0 0" />
    <parent
      link="base_link" />
    <child
      link="link_1" />
    <axis
      xyz="0 0 1" />
  </joint>
  <link
    name="link_2">
    <inertial>
      <origin
        xyz="0.062469 -0.0002125 -0.0043839"
        rpy="0 0 0" />
      <mass
        value="0.65668" />
      <inertia
        ixx="0.00030256"
        ixy="-4.5238E-08"
        ixz="4.7027E-05"
        iyy="0.00050509"
        iyz="-5.3372E-08"
        izz="0.00039508" />
    </inertial>
    <visual>
      <origin
        xyz="0 0 0"
        rpy="0 0 0" />
      <geometry>
        <mesh
          filename="package://manipulator_assembly_to_URDF/meshes/link_2.STL" />
      </geometry>
      <material
        name="">
        <color
          rgba="0 0 0 1" />
      </material>
    </visual>
    <collision>
      <origin
        xyz="0 0 0"
        rpy="0 0 0" />
      <geometry>
        <mesh
          filename="package://manipulator_assembly_to_URDF/meshes/link_2.STL" />
      </geometry>
    </collision>
  </link>
  <joint
    name="joint_2"
    type="continuous">
    <origin
      xyz="-0.00025 -0.0015763 0.030821"
      rpy="-3.1416 -1.5702 0" />
    <parent
      link="link_1" />
    <child
      link="link_2" />
    <axis
      xyz="0 0 1" />
  </joint>
  <link
    name="link_3">
    <inertial>
      <origin
        xyz="0.059564 -0.00080149 -0.0015856"
        rpy="0 0 0" />
      <mass
        value="0.090555" />
      <inertia
        ixx="8.4245E-05"
        ixy="8.3873E-07"
        ixz="-6.3077E-06"
        iyy="0.00043561"
        iyz="-6.7312E-07"
        izz="0.00039329" />
    </inertial>
    <visual>
      <origin
        xyz="0 0 0"
        rpy="0 0 0" />
      <geometry>
        <mesh
          filename="package://manipulator_assembly_to_URDF/meshes/link_3.STL" />
      </geometry>
      <material
        name="">
        <color
          rgba="0 0 0 1" />
      </material>
    </visual>
    <collision>
      <origin
        xyz="0 0 0"
        rpy="0 0 0" />
      <geometry>
        <mesh
          filename="package://manipulator_assembly_to_URDF/meshes/link_3.STL" />
      </geometry>
    </collision>
  </link>
  <joint
    name="joint_3"
    type="continuous">
    <origin
      xyz="0.17296 0 0.00014863"
      rpy="0.00058608 0 1.5708" />
    <parent
      link="link_2" />
    <child
      link="link_3" />
    <axis
      xyz="0 0 1" />
  </joint>
  <link
    name="gripper">
    <inertial>
      <origin
        xyz="-0.0013753 0.011708 0.021046"
        rpy="0 0 0" />
      <mass
        value="0.022996" />
      <inertia
        ixx="4.5836E-06"
        ixy="-3.611E-09"
        ixz="-4.4626E-09"
        iyy="5.9744E-06"
        iyz="8.7239E-08"
        izz="3.2255E-06" />
    </inertial>
    <visual>
      <origin
        xyz="0 0 0"
        rpy="0 0 0" />
      <geometry>
        <mesh
          filename="package://manipulator_assembly_to_URDF/meshes/gripper.STL" />
      </geometry>
      <material
        name="">
        <color
          rgba="1 0.54902 0 1" />
      </material>
    </visual>
    <collision>
      <origin
        xyz="0 0 0"
        rpy="0 0 0" />
      <geometry>
        <mesh
          filename="package://manipulator_assembly_to_URDF/meshes/gripper.STL" />
      </geometry>
    </collision>
  </link>
  <joint
    name="joint_4"
    type="continuous">
    <origin
      xyz="0.2032 0 0"
      rpy="0 -1.5708 0" />
    <parent
      link="link_3" />
    <child
      link="gripper" />
    <axis
      xyz="0 0 1" />
  </joint>
  <link
    name="left_finger">
    <inertial>
      <origin
        xyz="0.00085621 -0.0093356 -0.017664"
        rpy="0 0 0" />
      <mass
        value="0.006945" />
      <inertia
        ixx="1.3994E-06"
        ixy="9.5056E-14"
        ixz="-4.0439E-14"
        iyy="9.693E-07"
        iyz="-1.2261E-08"
        izz="5.2145E-07" />
    </inertial>
    <visual>
      <origin
        xyz="0 0 0"
        rpy="0 0 0" />
      <geometry>
        <mesh
          filename="package://manipulator_assembly_to_URDF/meshes/left_finger.STL" />
      </geometry>
      <material
        name="">
        <color
          rgba="1 0.54902 0 1" />
      </material>
    </visual>
    <collision>
      <origin
        xyz="0 0 0"
        rpy="0 0 0" />
      <geometry>
        <mesh
          filename="package://manipulator_assembly_to_URDF/meshes/left_finger.STL" />
      </geometry>
    </collision>
  </link>
  <joint
    name="lf_joint"
    type="prismatic">
    <origin
      xyz="0.032331 0 0.076026"
      rpy="0.35084 0 -1.5708" />
    <parent
      link="gripper" />
    <child
      link="left_finger" />
    <axis
      xyz="0 0 -1" />
    <limit
      lower="0"
      upper="0"
      effort="0"
      velocity="0" />
  </joint>
  <link
    name="right_finger">
    <inertial>
      <origin
        xyz="0.00086131 0.0093423 -0.017746"
        rpy="0 0 0" />
      <mass
        value="0.0069584" />
      <inertia
        ixx="1.3949E-06"
        ixy="-9.6372E-14"
        ixz="-3.7094E-14"
        iyy="9.6462E-07"
        iyz="1.1877E-08"
        izz="5.2161E-07" />
    </inertial>
    <visual>
      <origin
        xyz="0 0 0"
        rpy="0 0 0" />
      <geometry>
        <mesh
          filename="package://manipulator_assembly_to_URDF/meshes/right_finger.STL" />
      </geometry>
      <material
        name="">
        <color
          rgba="1 0.54902 0 1" />
      </material>
    </visual>
    <collision>
      <origin
        xyz="0 0 0"
        rpy="0 0 0" />
      <geometry>
        <mesh
          filename="package://manipulator_assembly_to_URDF/meshes/right_finger.STL" />
      </geometry>
    </collision>
  </link>
  <joint
    name="rf_joint"
    type="prismatic">
    <origin
      xyz="-0.030888 0 0.075969"
      rpy="-0.36176 0 -1.5708" />
    <parent
      link="gripper" />
    <child
      link="right_finger" />
    <axis
      xyz="0 0 -1" />
    <limit
      lower="0"
      upper="0"
      effort="0"
      velocity="0" />
  </joint>
</robot>